{
  final Error error=new Error("deliberate");
  Function<Throwable,Integer> fallback=new Function<Throwable,Integer>(){
    @Override public Integer apply(    Throwable t){
      throw error;
    }
  }
;
  ListenableFuture<Integer> failingFuture=immediateFailedFuture(new RuntimeException());
  try {
    getDone(catching(failingFuture,Throwable.class,fallback));
    fail();
  }
 catch (  ExecutionException expected) {
    assertSame(error,expected.getCause());
  }
}
