{
  final Error error=new Error("deliberate");
  AsyncFunction<Throwable,Integer> fallback=new AsyncFunction<Throwable,Integer>(){
    @Override public ListenableFuture<Integer> apply(    Throwable t) throws Exception {
      throw error;
    }
  }
;
  ListenableFuture<Integer> failingFuture=Futures.immediateFailedFuture(new RuntimeException());
  try {
    Futures.catchingAsync(failingFuture,Throwable.class,fallback).get();
    fail("An Exception should have been thrown!");
  }
 catch (  ExecutionException expected) {
    assertSame(error,expected.getCause());
  }
}
