{
  AsyncFunction<IOException,Integer> fallback=asyncFunctionReturningOne();
  ListenableFuture<Integer> originalFuture=immediateFailedFuture(new RuntimeException());
  ListenableFuture<Integer> faultTolerantFuture=catchingAsync(originalFuture,IOException.class,fallback);
  try {
    getDone(faultTolerantFuture);
    fail();
  }
 catch (  ExecutionException expected) {
    assertThat(expected.getCause()).isInstanceOf(RuntimeException.class);
  }
}
